INFO:     Will watch for changes in these directories: ['C:\\Users\\ACER\\Desktop\\AI For Farmers']
INFO:     Uvicorn running on http://0.0.0.0:8000 (Press CTRL+C to quit)
INFO:     Started reloader process [16948] using WatchFiles
Process SpawnProcess-1:
Traceback (most recent call last):
  File "C:\Users\ACER\AppData\Local\Packages\PythonSoftwareFoundation.Python.3.13_qbz5n2kfra8p0\LocalCache\local-packages\Python313\site-packages\pydantic\networks.py", line 946, in import_email_validator
    import email_validator
ModuleNotFoundError: No module named 'email_validator'

The above exception was the direct cause of the following exception:

Traceback (most recent call last):
  File "C:\Program Files\WindowsApps\PythonSoftwareFoundation.Python.3.13_3.13.2032.0_x64__qbz5n2kfra8p0\Lib\multiprocessing\process.py", line 313, in _bootstrap
    self.run()
    ~~~~~~~~^^
  File "C:\Program Files\WindowsApps\PythonSoftwareFoundation.Python.3.13_3.13.2032.0_x64__qbz5n2kfra8p0\Lib\multiprocessing\process.py", line 108, in run
    self._target(*self._args, **self._kwargs)
    ~~~~~~~~~~~~^^^^^^^^^^^^^^^^^^^^^^^^^^^^^
  File "C:\Users\ACER\AppData\Local\Packages\PythonSoftwareFoundation.Python.3.13_qbz5n2kfra8p0\LocalCache\local-packages\Python313\site-packages\uvicorn\_subprocess.py", line 80, in subprocess_started
    target(sockets=sockets)
    ~~~~~~^^^^^^^^^^^^^^^^^
  File "C:\Users\ACER\AppData\Local\Packages\PythonSoftwareFoundation.Python.3.13_qbz5n2kfra8p0\LocalCache\local-packages\Python313\site-packages\uvicorn\server.py", line 67, in run
    return asyncio.run(self.serve(sockets=sockets))
           ~~~~~~~~~~~^^^^^^^^^^^^^^^^^^^^^^^^^^^^^
  File "C:\Program Files\WindowsApps\PythonSoftwareFoundation.Python.3.13_3.13.2032.0_x64__qbz5n2kfra8p0\Lib\asyncio\runners.py", line 195, in run
    return runner.run(main)
           ~~~~~~~~~~^^^^^^
  File "C:\Program Files\WindowsApps\PythonSoftwareFoundation.Python.3.13_3.13.2032.0_x64__qbz5n2kfra8p0\Lib\asyncio\runners.py", line 118, in run
    return self._loop.run_until_complete(task)
           ~~~~~~~~~~~~~~~~~~~~~~~~~~~~~^^^^^^
  File "C:\Program Files\WindowsApps\PythonSoftwareFoundation.Python.3.13_3.13.2032.0_x64__qbz5n2kfra8p0\Lib\asyncio\base_events.py", line 725, in run_until_complete
    return future.result()
           ~~~~~~~~~~~~~^^
  File "C:\Users\ACER\AppData\Local\Packages\PythonSoftwareFoundation.Python.3.13_qbz5n2kfra8p0\LocalCache\local-packages\Python313\site-packages\uvicorn\server.py", line 71, in serve
    await self._serve(sockets)
  File "C:\Users\ACER\AppData\Local\Packages\PythonSoftwareFoundation.Python.3.13_qbz5n2kfra8p0\LocalCache\local-packages\Python313\site-packages\uvicorn\server.py", line 78, in _serve
    config.load()
    ~~~~~~~~~~~^^
  File "C:\Users\ACER\AppData\Local\Packages\PythonSoftwareFoundation.Python.3.13_qbz5n2kfra8p0\LocalCache\local-packages\Python313\site-packages\uvicorn\config.py", line 436, in load
    self.loaded_app = import_from_string(self.app)
                      ~~~~~~~~~~~~~~~~~~^^^^^^^^^^
  File "C:\Users\ACER\AppData\Local\Packages\PythonSoftwareFoundation.Python.3.13_qbz5n2kfra8p0\LocalCache\local-packages\Python313\site-packages\uvicorn\importer.py", line 19, in import_from_string
    module = importlib.import_module(module_str)
  File "C:\Program Files\WindowsApps\PythonSoftwareFoundation.Python.3.13_3.13.2032.0_x64__qbz5n2kfra8p0\Lib\importlib\__init__.py", line 88, in import_module
    return _bootstrap._gcd_import(name[level:], package, level)
           ~~~~~~~~~~~~~~~~~~~~~~^^^^^^^^^^^^^^^^^^^^^^^^^^^^^^
  File "<frozen importlib._bootstrap>", line 1387, in _gcd_import
  File "<frozen importlib._bootstrap>", line 1360, in _find_and_load
  File "<frozen importlib._bootstrap>", line 1331, in _find_and_load_unlocked
  File "<frozen importlib._bootstrap>", line 935, in _load_unlocked
  File "<frozen importlib._bootstrap_external>", line 1026, in exec_module
  File "<frozen importlib._bootstrap>", line 488, in _call_with_frames_removed
  File "C:\Users\ACER\Desktop\AI For Farmers\backend\main.py", line 11, in <module>
    from routers import auth, recommendations, soil, market, notifications
  File "C:\Users\ACER\Desktop\AI For Farmers\backend\routers\auth.py", line 5, in <module>
    from schemas import FarmerCreate, FarmerLogin, Token, FarmerResponse
  File "C:\Users\ACER\Desktop\AI For Farmers\backend\schemas.py", line 6, in <module>
    class FarmerCreate(BaseModel):
    ...<7 lines>...
        password: str
  File "C:\Users\ACER\AppData\Local\Packages\PythonSoftwareFoundation.Python.3.13_qbz5n2kfra8p0\LocalCache\local-packages\Python313\site-packages\pydantic\_internal\_model_construction.py", line 237, in __new__
    complete_model_class(
    ~~~~~~~~~~~~~~~~~~~~^
        cls,
        ^^^^
    ...<3 lines>...
        create_model_module=_create_model_module,
        ^^^^^^^^^^^^^^^^^^^^^^^^^^^^^^^^^^^^^^^^^
    )
    ^
  File "C:\Users\ACER\AppData\Local\Packages\PythonSoftwareFoundation.Python.3.13_qbz5n2kfra8p0\LocalCache\local-packages\Python313\site-packages\pydantic\_internal\_model_construction.py", line 597, in complete_model_class
    schema = gen_schema.generate_schema(cls)
  File "C:\Users\ACER\AppData\Local\Packages\PythonSoftwareFoundation.Python.3.13_qbz5n2kfra8p0\LocalCache\local-packages\Python313\site-packages\pydantic\_internal\_generate_schema.py", line 711, in generate_schema
    schema = self._generate_schema_inner(obj)
  File "C:\Users\ACER\AppData\Local\Packages\PythonSoftwareFoundation.Python.3.13_qbz5n2kfra8p0\LocalCache\local-packages\Python313\site-packages\pydantic\_internal\_generate_schema.py", line 1004, in _generate_schema_inner
    return self._model_schema(obj)
           ~~~~~~~~~~~~~~~~~~^^^^^
  File "C:\Users\ACER\AppData\Local\Packages\PythonSoftwareFoundation.Python.3.13_qbz5n2kfra8p0\LocalCache\local-packages\Python313\site-packages\pydantic\_internal\_generate_schema.py", line 837, in _model_schema
    {k: self._generate_md_field_schema(k, v, decorators) for k, v in fields.items()},
        ~~~~~~~~~~~~~~~~~~~~~~~~~~~~~~^^^^^^^^^^^^^^^^^^
  File "C:\Users\ACER\AppData\Local\Packages\PythonSoftwareFoundation.Python.3.13_qbz5n2kfra8p0\LocalCache\local-packages\Python313\site-packages\pydantic\_internal\_generate_schema.py", line 1206, in _generate_md_field_schema
    common_field = self._common_field_schema(name, field_info, decorators)
  File "C:\Users\ACER\AppData\Local\Packages\PythonSoftwareFoundation.Python.3.13_qbz5n2kfra8p0\LocalCache\local-packages\Python313\site-packages\pydantic\_internal\_generate_schema.py", line 1372, in _common_field_schema
    schema = self._apply_annotations(
        source_type,
        annotations + validators_from_decorators,
    )
  File "C:\Users\ACER\AppData\Local\Packages\PythonSoftwareFoundation.Python.3.13_qbz5n2kfra8p0\LocalCache\local-packages\Python313\site-packages\pydantic\_internal\_generate_schema.py", line 2297, in _apply_annotations
    schema = get_inner_schema(source_type)
  File "C:\Users\ACER\AppData\Local\Packages\PythonSoftwareFoundation.Python.3.13_qbz5n2kfra8p0\LocalCache\local-packages\Python313\site-packages\pydantic\_internal\_schema_generation_shared.py", line 83, in __call__
    schema = self._handler(source_type)
  File "C:\Users\ACER\AppData\Local\Packages\PythonSoftwareFoundation.Python.3.13_qbz5n2kfra8p0\LocalCache\local-packages\Python313\site-packages\pydantic\_internal\_generate_schema.py", line 2276, in inner_handler
    schema = self._generate_schema_from_get_schema_method(obj, source_type)
  File "C:\Users\ACER\AppData\Local\Packages\PythonSoftwareFoundation.Python.3.13_qbz5n2kfra8p0\LocalCache\local-packages\Python313\site-packages\pydantic\_internal\_generate_schema.py", line 900, in _generate_schema_from_get_schema_method
    schema = get_schema(
        source, CallbackGetCoreSchemaHandler(self._generate_schema_inner, self, ref_mode=ref_mode)
    )
  File "C:\Users\ACER\AppData\Local\Packages\PythonSoftwareFoundation.Python.3.13_qbz5n2kfra8p0\LocalCache\local-packages\Python313\site-packages\pydantic\networks.py", line 986, in __get_pydantic_core_schema__
    import_email_validator()
    ~~~~~~~~~~~~~~~~~~~~~~^^
  File "C:\Users\ACER\AppData\Local\Packages\PythonSoftwareFoundation.Python.3.13_qbz5n2kfra8p0\LocalCache\local-packages\Python313\site-packages\pydantic\networks.py", line 948, in import_email_validator
    raise ImportError('email-validator is not installed, run `pip install pydantic[email]`') from e
ImportError: email-validator is not installed, run `pip install pydantic[email]`
WARNING:  WatchFiles detected changes in 'backend\routers\soil.py'. Reloading...
 Process SpawnProcess-2:
Traceback (most recent call last):
  File "C:\Program Files\WindowsApps\PythonSoftwareFoundation.Python.3.13_3.13.2032.0_x64__qbz5n2kfra8p0\Lib\multiprocessing\process.py", line 313, in _bootstrap
    self.run()
    ~~~~~~~~^^
  File "C:\Program Files\WindowsApps\PythonSoftwareFoundation.Python.3.13_3.13.2032.0_x64__qbz5n2kfra8p0\Lib\multiprocessing\process.py", line 108, in run
    self._target(*self._args, **self._kwargs)
    ~~~~~~~~~~~~^^^^^^^^^^^^^^^^^^^^^^^^^^^^^
  File "C:\Users\ACER\AppData\Local\Packages\PythonSoftwareFoundation.Python.3.13_qbz5n2kfra8p0\LocalCache\local-packages\Python313\site-packages\uvicorn\_subprocess.py", line 80, in subprocess_started
    target(sockets=sockets)
    ~~~~~~^^^^^^^^^^^^^^^^^
  File "C:\Users\ACER\AppData\Local\Packages\PythonSoftwareFoundation.Python.3.13_qbz5n2kfra8p0\LocalCache\local-packages\Python313\site-packages\uvicorn\server.py", line 67, in run
    return asyncio.run(self.serve(sockets=sockets))
           ~~~~~~~~~~~^^^^^^^^^^^^^^^^^^^^^^^^^^^^^
  File "C:\Program Files\WindowsApps\PythonSoftwareFoundation.Python.3.13_3.13.2032.0_x64__qbz5n2kfra8p0\Lib\asyncio\runners.py", line 195, in run
    return runner.run(main)
           ~~~~~~~~~~^^^^^^
  File "C:\Program Files\WindowsApps\PythonSoftwareFoundation.Python.3.13_3.13.2032.0_x64__qbz5n2kfra8p0\Lib\asyncio\runners.py", line 118, in run
    return self._loop.run_until_complete(task)
           ~~~~~~~~~~~~~~~~~~~~~~~~~~~~~^^^^^^
  File "C:\Program Files\WindowsApps\PythonSoftwareFoundation.Python.3.13_3.13.2032.0_x64__qbz5n2kfra8p0\Lib\asyncio\base_events.py", line 725, in run_until_complete
    return future.result()
           ~~~~~~~~~~~~~^^
  File "C:\Users\ACER\AppData\Local\Packages\PythonSoftwareFoundation.Python.3.13_qbz5n2kfra8p0\LocalCache\local-packages\Python313\site-packages\uvicorn\server.py", line 71, in serve
    await self._serve(sockets)
  File "C:\Users\ACER\AppData\Local\Packages\PythonSoftwareFoundation.Python.3.13_qbz5n2kfra8p0\LocalCache\local-packages\Python313\site-packages\uvicorn\server.py", line 78, in _serve
    config.load()
    ~~~~~~~~~~~^^
  File "C:\Users\ACER\AppData\Local\Packages\PythonSoftwareFoundation.Python.3.13_qbz5n2kfra8p0\LocalCache\local-packages\Python313\site-packages\uvicorn\config.py", line 436, in load
    self.loaded_app = import_from_string(self.app)
                      ~~~~~~~~~~~~~~~~~~^^^^^^^^^^
  File "C:\Users\ACER\AppData\Local\Packages\PythonSoftwareFoundation.Python.3.13_qbz5n2kfra8p0\LocalCache\local-packages\Python313\site-packages\uvicorn\importer.py", line 22, in import_from_string
    raise exc from None
  File "C:\Users\ACER\AppData\Local\Packages\PythonSoftwareFoundation.Python.3.13_qbz5n2kfra8p0\LocalCache\local-packages\Python313\site-packages\uvicorn\importer.py", line 19, in import_from_string
    module = importlib.import_module(module_str)
  File "C:\Program Files\WindowsApps\PythonSoftwareFoundation.Python.3.13_3.13.2032.0_x64__qbz5n2kfra8p0\Lib\importlib\__init__.py", line 88, in import_module
    return _bootstrap._gcd_import(name[level:], package, level)
           ~~~~~~~~~~~~~~~~~~~~~~^^^^^^^^^^^^^^^^^^^^^^^^^^^^^^
  File "<frozen importlib._bootstrap>", line 1387, in _gcd_import
  File "<frozen importlib._bootstrap>", line 1360, in _find_and_load
  File "<frozen importlib._bootstrap>", line 1331, in _find_and_load_unlocked
  File "<frozen importlib._bootstrap>", line 935, in _load_unlocked
  File "<frozen importlib._bootstrap_external>", line 1026, in exec_module
  File "<frozen importlib._bootstrap>", line 488, in _call_with_frames_removed
  File "C:\Users\ACER\Desktop\AI For Farmers\backend\main.py", line 11, in <module>
    from routers import auth, recommendations, soil, market, notifications
  File "C:\Users\ACER\Desktop\AI For Farmers\backend\routers\recommendations.py", line 9, in <module>
    from routers.weather import get_weather_data
ModuleNotFoundError: No module named 'routers.weather'
WARNING:  WatchFiles detected changes in 'backend\routers\recommendations.py'. Reloading...
 Process SpawnProcess-3:
Traceback (most recent call last):
  File "C:\Users\ACER\AppData\Local\Packages\PythonSoftwareFoundation.Python.3.13_qbz5n2kfra8p0\LocalCache\local-packages\Python313\site-packages\sqlalchemy\engine\base.py", line 1963, in _exec_single_context
    self.dialect.do_execute(
    ~~~~~~~~~~~~~~~~~~~~~~~^
        cursor, str_statement, effective_parameters, context
        ^^^^^^^^^^^^^^^^^^^^^^^^^^^^^^^^^^^^^^^^^^^^^^^^^^^^
    )
    ^
  File "C:\Users\ACER\AppData\Local\Packages\PythonSoftwareFoundation.Python.3.13_qbz5n2kfra8p0\LocalCache\local-packages\Python313\site-packages\sqlalchemy\engine\default.py", line 943, in do_execute
    cursor.execute(statement, parameters)
    ~~~~~~~~~~~~~~^^^^^^^^^^^^^^^^^^^^^^^
sqlite3.OperationalError: table farmers already exists

The above exception was the direct cause of the following exception:

Traceback (most recent call last):
  File "C:\Program Files\WindowsApps\PythonSoftwareFoundation.Python.3.13_3.13.2032.0_x64__qbz5n2kfra8p0\Lib\multiprocessing\process.py", line 313, in _bootstrap
    self.run()
    ~~~~~~~~^^
  File "C:\Program Files\WindowsApps\PythonSoftwareFoundation.Python.3.13_3.13.2032.0_x64__qbz5n2kfra8p0\Lib\multiprocessing\process.py", line 108, in run
    self._target(*self._args, **self._kwargs)
    ~~~~~~~~~~~~^^^^^^^^^^^^^^^^^^^^^^^^^^^^^
  File "C:\Users\ACER\AppData\Local\Packages\PythonSoftwareFoundation.Python.3.13_qbz5n2kfra8p0\LocalCache\local-packages\Python313\site-packages\uvicorn\_subprocess.py", line 80, in subprocess_started
    target(sockets=sockets)
    ~~~~~~^^^^^^^^^^^^^^^^^
  File "C:\Users\ACER\AppData\Local\Packages\PythonSoftwareFoundation.Python.3.13_qbz5n2kfra8p0\LocalCache\local-packages\Python313\site-packages\uvicorn\server.py", line 67, in run
    return asyncio.run(self.serve(sockets=sockets))
           ~~~~~~~~~~~^^^^^^^^^^^^^^^^^^^^^^^^^^^^^
  File "C:\Program Files\WindowsApps\PythonSoftwareFoundation.Python.3.13_3.13.2032.0_x64__qbz5n2kfra8p0\Lib\asyncio\runners.py", line 195, in run
    return runner.run(main)
           ~~~~~~~~~~^^^^^^
  File "C:\Program Files\WindowsApps\PythonSoftwareFoundation.Python.3.13_3.13.2032.0_x64__qbz5n2kfra8p0\Lib\asyncio\runners.py", line 118, in run
    return self._loop.run_until_complete(task)
           ~~~~~~~~~~~~~~~~~~~~~~~~~~~~~^^^^^^
  File "C:\Program Files\WindowsApps\PythonSoftwareFoundation.Python.3.13_3.13.2032.0_x64__qbz5n2kfra8p0\Lib\asyncio\base_events.py", line 725, in run_until_complete
    return future.result()
           ~~~~~~~~~~~~~^^
  File "C:\Users\ACER\AppData\Local\Packages\PythonSoftwareFoundation.Python.3.13_qbz5n2kfra8p0\LocalCache\local-packages\Python313\site-packages\uvicorn\server.py", line 71, in serve
    await self._serve(sockets)
  File "C:\Users\ACER\AppData\Local\Packages\PythonSoftwareFoundation.Python.3.13_qbz5n2kfra8p0\LocalCache\local-packages\Python313\site-packages\uvicorn\server.py", line 78, in _serve
    config.load()
    ~~~~~~~~~~~^^
  File "C:\Users\ACER\AppData\Local\Packages\PythonSoftwareFoundation.Python.3.13_qbz5n2kfra8p0\LocalCache\local-packages\Python313\site-packages\uvicorn\config.py", line 436, in load
    self.loaded_app = import_from_string(self.app)
                      ~~~~~~~~~~~~~~~~~~^^^^^^^^^^
  File "C:\Users\ACER\AppData\Local\Packages\PythonSoftwareFoundation.Python.3.13_qbz5n2kfra8p0\LocalCache\local-packages\Python313\site-packages\uvicorn\importer.py", line 19, in import_from_string
    module = importlib.import_module(module_str)
  File "C:\Program Files\WindowsApps\PythonSoftwareFoundation.Python.3.13_3.13.2032.0_x64__qbz5n2kfra8p0\Lib\importlib\__init__.py", line 88, in import_module
    return _bootstrap._gcd_import(name[level:], package, level)
           ~~~~~~~~~~~~~~~~~~~~~~^^^^^^^^^^^^^^^^^^^^^^^^^^^^^^
  File "<frozen importlib._bootstrap>", line 1387, in _gcd_import
  File "<frozen importlib._bootstrap>", line 1360, in _find_and_load
  File "<frozen importlib._bootstrap>", line 1331, in _find_and_load_unlocked
  File "<frozen importlib._bootstrap>", line 935, in _load_unlocked
  File "<frozen importlib._bootstrap_external>", line 1026, in exec_module
  File "<frozen importlib._bootstrap>", line 488, in _call_with_frames_removed
  File "C:\Users\ACER\Desktop\AI For Farmers\backend\main.py", line 20, in <module>
    Base.metadata.create_all(bind=engine)
    ~~~~~~~~~~~~~~~~~~~~~~~~^^^^^^^^^^^^^
  File "C:\Users\ACER\AppData\Local\Packages\PythonSoftwareFoundation.Python.3.13_qbz5n2kfra8p0\LocalCache\local-packages\Python313\site-packages\sqlalchemy\sql\schema.py", line 5924, in create_all
    bind._run_ddl_visitor(
    ~~~~~~~~~~~~~~~~~~~~~^
        ddl.SchemaGenerator, self, checkfirst=checkfirst, tables=tables
        ^^^^^^^^^^^^^^^^^^^^^^^^^^^^^^^^^^^^^^^^^^^^^^^^^^^^^^^^^^^^^^^
    )
    ^
  File "C:\Users\ACER\AppData\Local\Packages\PythonSoftwareFoundation.Python.3.13_qbz5n2kfra8p0\LocalCache\local-packages\Python313\site-packages\sqlalchemy\engine\base.py", line 3248, in _run_ddl_visitor
    conn._run_ddl_visitor(visitorcallable, element, **kwargs)
    ~~~~~~~~~~~~~~~~~~~~~^^^^^^^^^^^^^^^^^^^^^^^^^^^^^^^^^^^^
  File "C:\Users\ACER\AppData\Local\Packages\PythonSoftwareFoundation.Python.3.13_qbz5n2kfra8p0\LocalCache\local-packages\Python313\site-packages\sqlalchemy\engine\base.py", line 2455, in _run_ddl_visitor
    ).traverse_single(element)
      ~~~~~~~~~~~~~~~^^^^^^^^^
  File "C:\Users\ACER\AppData\Local\Packages\PythonSoftwareFoundation.Python.3.13_qbz5n2kfra8p0\LocalCache\local-packages\Python313\site-packages\sqlalchemy\sql\visitors.py", line 664, in traverse_single
    return meth(obj, **kw)
  File "C:\Users\ACER\AppData\Local\Packages\PythonSoftwareFoundation.Python.3.13_qbz5n2kfra8p0\LocalCache\local-packages\Python313\site-packages\sqlalchemy\sql\ddl.py", line 982, in visit_metadata
    self.traverse_single(
    ~~~~~~~~~~~~~~~~~~~~^
        table,
        ^^^^^^
    ...<2 lines>...
        _is_metadata_operation=True,
        ^^^^^^^^^^^^^^^^^^^^^^^^^^^^
    )
    ^
  File "C:\Users\ACER\AppData\Local\Packages\PythonSoftwareFoundation.Python.3.13_qbz5n2kfra8p0\LocalCache\local-packages\Python313\site-packages\sqlalchemy\sql\visitors.py", line 664, in traverse_single
    return meth(obj, **kw)
  File "C:\Users\ACER\AppData\Local\Packages\PythonSoftwareFoundation.Python.3.13_qbz5n2kfra8p0\LocalCache\local-packages\Python313\site-packages\sqlalchemy\sql\ddl.py", line 1020, in visit_table
    )._invoke_with(self.connection)
      ~~~~~~~~~~~~^^^^^^^^^^^^^^^^^
  File "C:\Users\ACER\AppData\Local\Packages\PythonSoftwareFoundation.Python.3.13_qbz5n2kfra8p0\LocalCache\local-packages\Python313\site-packages\sqlalchemy\sql\ddl.py", line 321, in _invoke_with
    return bind.execute(self)
           ~~~~~~~~~~~~^^^^^^
  File "C:\Users\ACER\AppData\Local\Packages\PythonSoftwareFoundation.Python.3.13_qbz5n2kfra8p0\LocalCache\local-packages\Python313\site-packages\sqlalchemy\engine\base.py", line 1415, in execute
    return meth(
        self,
        distilled_parameters,
        execution_options or NO_OPTIONS,
    )
  File "C:\Users\ACER\AppData\Local\Packages\PythonSoftwareFoundation.Python.3.13_qbz5n2kfra8p0\LocalCache\local-packages\Python313\site-packages\sqlalchemy\sql\ddl.py", line 187, in _execute_on_connection
    return connection._execute_ddl(
           ~~~~~~~~~~~~~~~~~~~~~~~^
        self, distilled_params, execution_options
        ^^^^^^^^^^^^^^^^^^^^^^^^^^^^^^^^^^^^^^^^^
    )
    ^
  File "C:\Users\ACER\AppData\Local\Packages\PythonSoftwareFoundation.Python.3.13_qbz5n2kfra8p0\LocalCache\local-packages\Python313\site-packages\sqlalchemy\engine\base.py", line 1526, in _execute_ddl
    ret = self._execute_context(
        dialect,
    ...<4 lines>...
        compiled,
    )
  File "C:\Users\ACER\AppData\Local\Packages\PythonSoftwareFoundation.Python.3.13_qbz5n2kfra8p0\LocalCache\local-packages\Python313\site-packages\sqlalchemy\engine\base.py", line 1842, in _execute_context
    return self._exec_single_context(
           ~~~~~~~~~~~~~~~~~~~~~~~~~^
        dialect, context, statement, parameters
        ^^^^^^^^^^^^^^^^^^^^^^^^^^^^^^^^^^^^^^^
    )
    ^
  File "C:\Users\ACER\AppData\Local\Packages\PythonSoftwareFoundation.Python.3.13_qbz5n2kfra8p0\LocalCache\local-packages\Python313\site-packages\sqlalchemy\engine\base.py", line 1982, in _exec_single_context
    self._handle_dbapi_exception(
    ~~~~~~~~~~~~~~~~~~~~~~~~~~~~^
        e, str_statement, effective_parameters, cursor, context
        ^^^^^^^^^^^^^^^^^^^^^^^^^^^^^^^^^^^^^^^^^^^^^^^^^^^^^^^
    )
    ^
  File "C:\Users\ACER\AppData\Local\Packages\PythonSoftwareFoundation.Python.3.13_qbz5n2kfra8p0\LocalCache\local-packages\Python313\site-packages\sqlalchemy\engine\base.py", line 2351, in _handle_dbapi_exception
    raise sqlalchemy_exception.with_traceback(exc_info[2]) from e
  File "C:\Users\ACER\AppData\Local\Packages\PythonSoftwareFoundation.Python.3.13_qbz5n2kfra8p0\LocalCache\local-packages\Python313\site-packages\sqlalchemy\engine\base.py", line 1963, in _exec_single_context
    self.dialect.do_execute(
    ~~~~~~~~~~~~~~~~~~~~~~~^
        cursor, str_statement, effective_parameters, context
        ^^^^^^^^^^^^^^^^^^^^^^^^^^^^^^^^^^^^^^^^^^^^^^^^^^^^
    )
    ^
  File "C:\Users\ACER\AppData\Local\Packages\PythonSoftwareFoundation.Python.3.13_qbz5n2kfra8p0\LocalCache\local-packages\Python313\site-packages\sqlalchemy\engine\default.py", line 943, in do_execute
    cursor.execute(statement, parameters)
    ~~~~~~~~~~~~~~^^^^^^^^^^^^^^^^^^^^^^^
sqlalchemy.exc.OperationalError: (sqlite3.OperationalError) table farmers already exists
[SQL: 
CREATE TABLE farmers (
	id INTEGER NOT NULL, 
	name VARCHAR(100) NOT NULL, 
	email VARCHAR(100) NOT NULL, 
	phone VARCHAR(15) NOT NULL, 
	location VARCHAR(100) NOT NULL, 
	state VARCHAR(50) NOT NULL, 
	district VARCHAR(50) NOT NULL, 
	village VARCHAR(50), 
	hashed_password VARCHAR(255) NOT NULL, 
	is_active BOOLEAN, 
	created_at DATETIME DEFAULT CURRENT_TIMESTAMP, 
	updated_at DATETIME, 
	PRIMARY KEY (id)
)

]
(Background on this error at: https://sqlalche.me/e/20/e3q8)
WARNING:  WatchFiles detected changes in 'backend\routers\soil.py'. Reloading...
 WARNING:  WatchFiles detected changes in 'backend\routers\recommendations.py'. Reloading...
 Process SpawnProcess-4:
Traceback (most recent call last):
  File "C:\Program Files\WindowsApps\PythonSoftwareFoundation.Python.3.13_3.13.2032.0_x64__qbz5n2kfra8p0\Lib\multiprocessing\process.py", line 313, in _bootstrap
    self.run()
    ~~~~~~~~^^
  File "C:\Program Files\WindowsApps\PythonSoftwareFoundation.Python.3.13_3.13.2032.0_x64__qbz5n2kfra8p0\Lib\multiprocessing\process.py", line 108, in run
    self._target(*self._args, **self._kwargs)
    ~~~~~~~~~~~~^^^^^^^^^^^^^^^^^^^^^^^^^^^^^
  File "C:\Users\ACER\AppData\Local\Packages\PythonSoftwareFoundation.Python.3.13_qbz5n2kfra8p0\LocalCache\local-packages\Python313\site-packages\uvicorn\_subprocess.py", line 73, in subprocess_started
    sys.stdin = os.fdopen(stdin_fileno)  # pragma: full coverage
                ~~~~~~~~~^^^^^^^^^^^^^^
  File "<frozen os>", line 1069, in fdopen
  File "<frozen codecs>", line 312, in __init__
KeyboardInterrupt
INFO:     Started server process [12256]
INFO:     Waiting for application startup.
INFO:     Application startup complete.
WARNING:  WatchFiles detected changes in 'backend\routers\market.py'. Reloading...
 INFO:     Shutting down
INFO:     Waiting for application shutdown.
INFO:     Application shutdown complete.
INFO:     Finished server process [12256]
WARNING:  WatchFiles detected changes in 'backend\ml\train_yield_model.py', 'backend\ml\train_price_model.py', 'backend\routers\recommendations.py', 'backend\ml\train_crop_model.py', 'backend\main.py', 'backend\routers\soil.py', 'backend\routers\api_v2.py', 'backend\ml\train_disease_model.py', 'backend\services\ml_service.py', 'backend\services\__init__.py', 'backend\ml\train_all.py', 'backend\ml\train_faq_model.py', 'backend\ml\train_fertilizer_model.py', 'backend\run.py', 'backend\routers\notifications.py', 'backend\ml\kaggle_manager.py', 'backend\ml\train_pest_model.py'. Reloading...
 Process SpawnProcess-6:
Traceback (most recent call last):
  File "C:\Program Files\WindowsApps\PythonSoftwareFoundation.Python.3.13_3.13.2032.0_x64__qbz5n2kfra8p0\Lib\multiprocessing\process.py", line 313, in _bootstrap
    self.run()
    ~~~~~~~~^^
  File "C:\Program Files\WindowsApps\PythonSoftwareFoundation.Python.3.13_3.13.2032.0_x64__qbz5n2kfra8p0\Lib\multiprocessing\process.py", line 108, in run
    self._target(*self._args, **self._kwargs)
    ~~~~~~~~~~~~^^^^^^^^^^^^^^^^^^^^^^^^^^^^^
  File "C:\Users\ACER\AppData\Local\Packages\PythonSoftwareFoundation.Python.3.13_qbz5n2kfra8p0\LocalCache\local-packages\Python313\site-packages\uvicorn\_subprocess.py", line 73, in subprocess_started
    sys.stdin = os.fdopen(stdin_fileno)  # pragma: full coverage
                ~~~~~~~~~^^^^^^^^^^^^^^
  File "<frozen os>", line 1069, in fdopen
  File "<frozen codecs>", line 312, in __init__
KeyboardInterrupt
INFO:     Started server process [23284]
INFO:     Waiting for application startup.
INFO:     Application startup complete.
INFO:     127.0.0.1:62619 - "GET / HTTP/1.1" 200 OK
INFO:     127.0.0.1:62619 - "GET /favicon.ico HTTP/1.1" 404 Not Found
INFO:     127.0.0.1:64214 - "GET / HTTP/1.1" 200 OK
WARNING:  WatchFiles detected changes in 'backend\routers\market.py'. Reloading...
 INFO:     Shutting down
INFO:     Waiting for application shutdown.
INFO:     Application shutdown complete.
INFO:     Finished server process [23284]
